Workbook

Sheet Cover
B2: CAMECO CORPORATION (CCJ)
B3: DCF Financial Model
B4: Nixon Soetedja
B5: Currency: $CDN thousands | Actuals: 2021–2025
B8: Tab | C8: Description
B9: Income Statement | C9: Revenue, EBIT, EBT, Net Earnings, EPS — 2021A to 2025A
B10: Balance Sheet | C10: Assets, Liabilities, Equity — 2021A to 2025A
B11: Cash Flow | C11: Operating / Investing / Financing + FCF bridge — 2021A to 2025A
B12: Projections | C12: Key assumptions: uranium price, volume, margins, WACC [to build]
B13: DCF | C13: Intrinsic value per share via discounted free cash flows [to build]
B14: Comps | C14: Peer multiples: Kazatomprom, NexGen, Denison [to build]
B17: Case | C17: 2
B18: 1 | C18: Base
B19: 2 | C19: Upside

Sheet Income Statement
C2: CAMECO CORPORATION — INCOME STATEMENT
C3: All figures in $CDN thousands | IFRS | Year ended December 31
D5: 2021A | E5: 2022A | F5: 2023A | G5: 2024A | H5: 2025A | I5: 2026AE | J5: 2027E | K5: 2028E | L5: 2029E | M5: 2030E | N5: 2031E | O5: 2032E | P5: 2033E | Q5: 2034E | R5: 2035E
C7: Revenue
C8: Revenue from products and services | D8: 1474984 | E8: 1868003 | F8: 2587758 | G8: 3135772 | H8: 3481933 | I8: 0 | J8: 0 | K8: =J8+(J8*Assumptions!P8) -> 0 | L8: =K8+(K8*Assumptions!Q8) -> 0 | M8: =L8+(L8*Assumptions!R8) -> 0 | N8: =M8+(M8*Assumptions!S8) -> 0 | O8: =N8+(N8*Assumptions!T8) -> 0 | P8: =O8+(O8*Assumptions!U8) -> 0 | Q8: =P8+(P8*Assumptions!V8) -> 0 | R8: =Q8+(Q8*Assumptions!W8) -> 0
C9: ='Segment Drivers'!A36 -> Uranium Revenue | D9: ='Segment Drivers'!B36 -> 1055000 | E9: ='Segment Drivers'!C36 -> 1480000 | F9: ='Segment Drivers'!D36 -> 2152000 | G9: ='Segment Drivers'!E36 -> 2677000 | H9: ='Segment Drivers'!F36 -> 2874000 | I9: ='2026 Interim'!C126 -> 2746070 | J9: ='Uranium Spot Rate'!G10 -> 3209950.8 | K9: ='Uranium Spot Rate'!H10 -> 3649839.6 | L9: ='Uranium Spot Rate'!I10 -> 4129150.4 | M9: ='Uranium Spot Rate'!J10 -> 4650898.5 | N9: ='Uranium Spot Rate'!K10 -> 5218311 | O9: ='Uranium Spot Rate'!L10 -> 5834840.6 | P9: ='Uranium Spot Rate'!M10 -> 6504180.5 | Q9: ='Uranium Spot Rate'!N10 -> 7230280.6 | R9: ='Uranium Spot Rate'!O10 -> 8017364.4
C10: ='Segment Drivers'!A37 -> Fuel Services Revenue | D10: ='Segment Drivers'!B37 -> 404000 | E10: ='Segment Drivers'!C37 -> 365000 | F10: ='Segment Drivers'!D37 -> 426000 | G10: ='Segment Drivers'!E37 -> 459000 | H10: ='Segment Drivers'!F37 -> 562000 | I10: ='2026 Interim'!C127 -> 572000 | J10: =I10+(I10*Assumptions!O10) -> 661420.56 | K10: =J10+(J10*Assumptions!P10) -> 764820.2 | L10: =K10+(K10*Assumptions!Q10) -> 884384.28 | M10: =L10+(L10*Assumptions!R10) -> 1022639.8 | N10: =M10+(M10*Assumptions!S10) -> 1182508.7 | O10: =N10+(N10*Assumptions!T10) -> 1367369.8 | P10: =O10+(O10*Assumptions!U10) -> 1581130.3 | Q10: =P10+(P10*Assumptions!V10) -> 1828307.8 | R10: =Q10+(Q10*Assumptions!W10) -> 2114126.6
C11: Other | D11: 0 | E11: 0 | F11: 0 | G11: 0 | H11: 46 | I11: - | J11: - | K11: - | L11: - | M11: - | N11: - | O11: - | P11: - | Q11: - | R11: -
C12: Total Revenue | D12: =SUM(D9:D11) -> 1459000 | E12: =SUM(E9:E11) -> 1845000 | F12: =SUM(F9:F11) -> 2578000 | G12: =SUM(G9:G11) -> 3136000 | H12: =SUM(H9:H11) -> 3436046 | I12: =SUM(I9:I11) -> 3318070 | J12: =SUM(J9:J11) -> 3871371.4 | K12: =SUM(K9:K11) -> 4414659.8 | ... R12: =SUM(R9:R11) -> 10131491
C14: Cost of Sales
C15: Cost of products and services sold | D15: 1282635 | E15: 1457336 | F15: 1805768 | G15: 2072488 | H15: 2218566 | I15: 0 | J15: 0 | K15: =J15*(1+Assumptions!P15) -> 0 | L15: =K15*(1+Assumptions!Q15) -> 0 | M15: =L15*(1+Assumptions!R15) -> 0 | N15: =M15*(1+Assumptions!S15) -> 0 | O15: =N15*(1+Assumptions!T15) -> 0 | P15: =O15*(1+Assumptions!T15) -> 0 | Q15: =P15*(1+Assumptions!T15) -> 0 | R15: =Q15*(1+Assumptions!U15) -> 0
C16: Uranium cost of products sold | D16: 1028816 | E16: 1223558 | F16: 1532316 | G16: 1757155 | H16: 1824516 | I16: ='2026 Interim'!C133 -> 1677200 | J16: =I16*(1+Assumptions!O16) -> 1837882 | K16: =J16*(1+Assumptions!P16) -> 2013957.9 | L16: =K16*(1+Assumptions!Q16) -> 2206902.6 | M16: =L16*(1+Assumptions!R16) -> 2418332 | N16: =M16*(1+Assumptions!S16) -> 2650017.2 | O16: =N16*(1+Assumptions!T16) -> 2903898.7 | P16: =O16*(1+Assumptions!T16) -> 3182103 | Q16: =P16*(1+Assumptions!T16) -> 3486960.2 | R16: =Q16*(1+Assumptions!U16) -> 3821024
C17: Fuel Services cost of products sold | D17: 242574 | E17: 215660 | F17: 266062 | G17: 316040 | H17: 348800 | I17: ='2026 Interim'!C134 -> 379118 | J17: =I17*(1+Assumptions!O17) -> 418416.52 | K17: =J17*(1+Assumptions!P17) -> 461788.65 | L17: =K17*(1+Assumptions!Q17) -> 509656.63 | M17: =L17*(1+Assumptions!R17) -> 562486.49 | N17: =M17*(1+Assumptions!S17) -> 620792.58 | O17: =N17*(1+Assumptions!T17) -> 685142.56 | P17: =O17*(1+Assumptions!T17) -> 756162.9 | Q17: =P17*(1+Assumptions!T17) -> 834545.06 | R17: =Q17*(1+Assumptions!U17) -> 921052.13
C18: Depreciation and amortization (COGS) | D18: 190415 | E18: 177376 | F18: 220324 | G18: 280702 | H18: 293094 | I18: ='2026 Interim'!C135 -> 278514 | J18: =I18*(1+Assumptions!O18) -> 290809.41 | K18: =J18*(1+Assumptions!P18) -> 303647.61 | L18: =K18*(1+Assumptions!Q18) -> 317052.58 | M18: =L18*(1+Assumptions!R18) -> 331049.33 | N18: =M18*(1+Assumptions!S18) -> 345663.99 | O18: =N18*(1+Assumptions!T18) -> 360923.83 | P18: =O18*(1+Assumptions!T18) -> 376857.34 | Q18: =P18*(1+Assumptions!T18) -> 393494.26 | R18: =Q18*(1+Assumptions!U18) -> 410865.64
C19: Total cost of sales | D19: 1473050 | E19: 1634712 | F19: 2026092 | G19: 2353190 | H19: 2511660 | I19: =SUM(I16:I18) -> 2334832 | J19: =SUM(J16:J18) -> 2547107.9 | K19: =SUM(K16:K18) -> 2779394.2 | L19: =SUM(L16:L18) -> 3033611.8 | M19: =SUM(M16:M18) -> 3311867.8 | N19: =SUM(N16:N18) -> 3616473.8 | O19: =SUM(O16:O18) -> 3949965.1 | P19: =SUM(P16:P18) -> 4315123.2 | ... R19: =SUM(R16:R18) -> 5152941.7
C21: Gross Profit | D21: 1934 | E21: 233291 | F21: 561666 | G21: 782582 | H21: 970273 | I21: =I12-I19 -> 983238 | J21: =J12-J19 -> 1324263.5 | K21: =K12-K19 -> 1635265.7 | L21: =L12-L19 -> 1979922.9 | M21: =M12-M19 -> 2361670.5 | N21: =N12-N19 -> 2784345.9 | O21: =O12-O19 -> 3252245.3 | P21: =P12-P19 -> 3770187.6 | ... R21: =R12-R19 -> 4978549.2
C23: Operating Expenses
C24: Administration | D24: 127566 | E24: 172029 | F24: 245539 | G24: 253150 | H24: 311250 | I24: ='2026 Interim'!C141 -> 398910 | J24: =J12*Assumptions!O24 -> 345173.75 | K24: =K12*Assumptions!P24 -> 393613.66 | L24: =L12*Assumptions!Q24 -> 447009.7 | M24: =M12*Assumptions!R24 -> 505856.01 | N24: =N12*Assumptions!S24 -> 570700.84 | O24: =O12*Assumptions!T24 -> 642153.31 | P24: =P12*Assumptions!T24 -> 720891.06 | Q24: =Q12*Assumptions!T24 -> 807669.07 | R24: =R12*Assumptions!U24 -> 903329.68
C25: Exploration | D25: 8016 | E25: 10578 | F25: 17551 | G25: 19419 | H25: 27630 | I25: ='2026 Interim'!C142 -> 31782 | J25: =J12*Assumptions!O25 -> 23448.685 | K25: =K12*Assumptions!P25 -> 26739.353 | L25: =L12*Assumptions!Q25 -> 30366.705 | M25: =M12*Assumptions!R25 -> 34364.311 | N25: =N12*Assumptions!S25 -> 38769.415 | O25: =O12*Assumptions!T25 -> 43623.395 | P25: =P12*Assumptions!T25 -> 48972.285 | Q25: =Q12*Assumptions!T25 -> 54867.375 | R25: =R12*Assumptions!U25 -> 61365.887
C26: Research and development | D26: 7168 | E26: 12175 | F26: 21036 | G26: 36540 | H26: 38467 | I26: ='2026 Interim'!C143 -> 47220 | J26: =J12*Assumptions!O26 -> 30316.196 | K26: =K12*Assumptions!P26 -> 34570.616 | L26: =L12*Assumptions!Q26 -> 39260.325 | M26: =M12*Assumptions!R26 -> 44428.726 | N26: =N12*Assumptions!S26 -> 50123.97 | O26: =O12*Assumptions!T26 -> 56399.555 | P26: =P12*Assumptions!T26 -> 63314.997 | Q26: =Q12*Assumptions!T26 -> 70936.605 | R26: =R12*Assumptions!U26 -> 79338.362
C27: Other operating expense (income) | D27: -8407 | E27: 22944 | F27: -7509 | G27: -37683 | H27: -28333 | I27: ='2026 Interim'!C144 -> 7592 | J27: =J12*Assumptions!O27 -> -7989.9098 | K27: =K12*Assumptions!P27 -> -9111.1728 | L27: =L12*Assumptions!Q27 -> -10347.158 | M27: =M12*Assumptions!R27 -> -11709.303 | N27: =N12*Assumptions!S27 -> -13210.299 | O27: =O12*Assumptions!T27 -> -14864.245 | P27: =P12*Assumptions!T27 -> -16686.827 | Q27: =Q12*Assumptions!T27 -> -18695.521 | R27: =R12*Assumptions!U27 -> -20909.825
C28: Loss on disposal of assets | D28: 3803 | E28: 514 | F28: 2188 | G28: 1042 | H28: 3117 | I28: ='2026 Interim'!C145 -> 1986 | J28: =J12*Assumptions!O28 -> 3935.4048 | K28: =K12*Assumptions!P28 -> 4487.6794 | L28: =L12*Assumptions!Q28 -> 5096.4598 | M28: =M12*Assumptions!R28 -> 5767.38 | N28: =N12*Assumptions!S28 -> 6506.6908 | O28: =O12*Assumptions!T28 -> 7321.3367 | P28: =P12*Assumptions!T28 -> 8219.0438 | Q28: =Q12*Assumptions!T28 -> 9208.4198 | R28: =R12*Assumptions!U28 -> 10299.068
C30: Earnings (Loss) from Operations — EBIT | D30: -136212 | E30: 15051 | F30: 282861 | G30: 510114 | H30: 618142 | I30: =I21-I24-I25-I26-I27-I28 -> 495748 | J30: =J21-J24-J25-J26-J27-J28 -> 929379.34 | K30: =K21-K24-K25-K26-K27-K28 -> 1184965.5 | L30: =L21-L24-L25-L26-L27-L28 -> 1468536.9 | M30: =M21-M24-M25-M26-M27-M28 -> 1782963.3 | N30: =N21-N24-N25-N26-N27-N28 -> 2131455.3 | O30: =O21-O24-O25-O26-O27-O28 -> 2517612 | P30: =P21-P24-P25-P26-P27-P28 -> 2945477 | ... R30: =R21-R24-R25-R26-R27-R28 -> 3945126
C32: Non-Operating Items
C33: Finance costs | D33: -76612 | E33: -85728 | F33: -115869 | G33: -147171 | H33: -115175 | I33: ='2026 Interim'!C150 -> -115002 | J33: =I33*(1+Assumptions!O33) -> -108101.88 | K33: =J33*(1+Assumptions!P33) -> -101615.77 | L33: =K33*(1+Assumptions!Q33) -> -95518.821 | M33: =L33*(1+Assumptions!R33) -> -89787.692 | N33: =M33*(1+Assumptions!S33) -> -84400.43 | O33: =N33*(1+Assumptions!T33) -> -79336.405 | P33: =O33*(1+Assumptions!T33) -> -74576.22 | Q33: =P33*(1+Assumptions!T33) -> -70101.647 | R33: =Q33*(1+Assumptions!U33) -> -65895.548
C34: Gain (loss) on derivatives | D34: 12529 | E34: -72949 | F34: 37791 | G34: -183103 | H34: 95017 | I34: ='2026 Interim'!C151 -> -204082 | J34: 0 | K34: 0 | L34: 0 | M34: 0 | N34: 0 | O34: 0 | P34: 0 | Q34: 0 | R34: 0
C35: Finance income | D35: 6804 | E35: 37499 | F35: 111670 | G35: 21228 | H35: 23172 | I35: ='2026 Interim'!C152 -> 35698 | J35: 0 | K35: 0 | L35: 0 | M35: 0 | N35: 0 | O35: 0 | P35: 0 | Q35: 0 | R35: 0
C36: Share of earnings (loss) from equity-accounted investees | D36: 68283 | E36: 93988 | F36: 154462 | G36: -10844 | H36: 216386 | I36: ='2026 Interim'!C153 -> 148952 | J36: =Westinghouse!G8 -> 163847.2 | K36: =Westinghouse!H8 -> 180231.92 | L36: =Westinghouse!I8 -> 224028.28 | M36: =Westinghouse!J8 -> 253151.95 | N36: =Westinghouse!K8 -> 286061.71 | O36: =Westinghouse!L8 -> 361998.09 | P36: =Westinghouse!M8 -> 419917.78 | Q36: =Westinghouse!N8 -> 487104.63 | R36: =Westinghouse!O8 -> 565041.37
C37: Foreign exchange gains (losses) [note: included in Other income 2021-2023] | D37: 0 | E37: 0 | F37: 0 | G37: 65517 | H37: -61740 | I37: ='2026 Interim'!C154 -> 54620 | J37: 0 | K37: 0 | L37: 0 | M37: 0 | N37: 0 | O37: 0 | P37: 0 | Q37: 0 | R37: 0
C38: Other income | D38: 21353 | E38: 96934 | F38: 16238 | G38: 975 | H38: 1459 | I38: ='2026 Interim'!C155 -> 1520 | J38: 0 | K38: 0 | L38: 0 | M38: 0 | N38: 0 | O38: 0 | P38: 0 | Q38: 0 | R38: 0
C40: Earnings (Loss) Before Income Taxes — EBT | D40: -103855 | E40: 84795 | F40: 487153 | G40: 256716 | H40: 777261 | I40: =I30+I33+I34+I35+I36+I37+I38 -> 417454 | J40: =J30+J33+J34+J35+J36+J37+J38 -> 985124.66 | K40: =K30+K33+K34+K35+K36+K37+K38 -> 1263581.7 | L40: =L30+L33+L34+L35+L36+L37+L38 -> 1597046.3 | M40: =M30+M33+M34+M35+M36+M37+M38 -> 1946327.6 | N40: =N30+N33+N34+N35+N36+N37+N38 -> 2333116.6 | O40: =O30+O33+O34+O35+O36+O37+O38 -> 2800273.7 | P40: =P30+P33+P34+P35+P36+P37+P38 -> 3290818.6 | ... R40: =R30+R33+R34+R35+R36+R37+R38 -> 4444271.8
C42: Income tax expense (recovery) | D42: -1201 | E42: -4469 | F42: 126337 | G42: 84874 | H42: 187719 | I42: =I40*Assumptions!N42 -> 123138.87 | J42: =J40*Assumptions!O42 -> 290588.03 | K42: =K40*Assumptions!P42 -> 372726.13 | L42: =L40*Assumptions!Q42 -> 471090.17 | M42: =M40*Assumptions!R42 -> 574119.73 | N42: =N40*Assumptions!S42 -> 688213.15 | O42: =O40*Assumptions!T42 -> 826013.23 | P42: =P40*Assumptions!T42 -> 970712.16 | Q42: =Q40*Assumptions!T42 -> 1131706.3 | R42: =R40*Assumptions!U42 -> 1310953.1
C44: Net Earnings (Loss) | D44: -102654 | E44: 89264 | F44: 360816 | G44: 171842 | H44: 589542 | I44: =I40-I42 -> 294315.13 | J44: =J40-J42 -> 694536.63 | K44: =K40-K42 -> 890855.53 | L44: =L40-L42 -> 1125956.2 | M44: =M40-M42 -> 1372207.9 | N44: =N40-N42 -> 1644903.4 | O44: =O40-O42 -> 1974260.4 | P44: =P40-P42 -> 2320106.4 | ... R44: =R40-R42 -> 3133318.8
C54: Attributable to:
C55: Equity holders of Cameco | D55: -102577 | E55: 89382 | F55: 360847 | G55: 171853 | H55: 589577 | I55: =I44-I56 -> 294350.13 | J55: =J44-J56 -> 694571.63 | K55: =K44-K56 -> 890890.53 | L55: =L44-L56 -> 1125991.2 | M55: =M44-M56 -> 1372242.9 | N55: =N44-N56 -> 1644938.4 | O55: =O44-O56 -> 1974295.4 | P55: =P44-P56 -> 2320141.4 | ... R55: =R44-R56 -> 3133352.8
C56: Non-controlling interests (NCI) | D56: -77 | E56: -118 | F56: -31 | G56: -11 | H56: -35 | I56: -35 | J56: -35 | K56: -35 | L56: -35 | M56: -35 | N56: -35 | O56: -35 | P56: -35 | Q56: -35 | R56: -34
C58: Per Share Data (equity holders)
C59: Basic EPS ($CDN) | D59: -0.26 | E59: 0.22 | F59: 0.83 | G59: 0.4 | H59: 1.35 | I59: =I55/436720 -> 0.67400195 | J59: =J55/436720 -> 1.5904278 | K59: =K55/436720 -> 2.0399582 | L59: =L55/436720 -> 2.5782908 | M59: =M55/436720 -> 3.1421571 | N59: =N55/436720 -> 3.7665745 | O59: =O55/436720 -> 4.5207351 | P59: =P55/436720 -> 5.3126521 | ... R59: =R55/436720 -> 7.1747407
C60: Diluted EPS ($CDN) | D60: -0.26 | E60: 0.22 | F60: 0.83 | G60: 0.39 | H60: 1.35 | I60: =I55/436720 -> 0.67400195 | J60: =J55/436720 -> 1.5904278 | K60: =K55/436720 -> 2.0399582 | L60: =L55/436720 -> 2.5782908 | M60: =M55/436720 -> 3.1421571 | N60: =N55/436720 -> 3.7665745 | O60: =O55/436720 -> 4.5207351 | P60: =P55/436720 -> 5.3126521 | ... R60: =R55/436720 -> 7.1747407

Sheet Balance Sheet
C2: CAMECO CORPORATION — BALANCE SHEET
C3: All figures in $CDN thousands | IFRS | As at December 31
D5: 2021A | E5: 2022A | F5: 2023A | G5: 2024A | H5: 2025A | I5: 2026E | J5: 2027E | K5: 2028E | L5: 2029E | M5: 2030E | N5: 2031E | O5: 2032E | P5: 2033E | Q5: 2034E | R5: 2035E
C7: ASSETS
C8: Current Assets
C9: Cash and cash equivalents | D9: 1247447 | E9: 1143674 | F9: 566809 | G9: 600462 | H9: 1114860 | I9: =I53-I11-I12-I13-I14-I15-I24 -> 1628365.7 | J9: =J53-J11-J12-J13-J14-J15-J24 -> 2554034.2 | K9: =K53-K11-K12-K13-K14-K15-K24 -> 3715373.4 | L9: =L53-L11-L12-L13-L14-L15-L24 -> 5118984.2 | M9: =M53-M11-M12-M13-M14-M15-M24 -> 6795867.4 | N9: =N53-N11-N12-N13-N14-N15-N24 -> 8774360.2 | O9: =O53-O11-O12-O13-O14-O15-O24 -> 11074324 | P9: =P53-P11-P12-P13-P14-P15-P24 -> 13737093 | ... R9: =R53-R11-R12-R13-R14-R15-R24 -> 20299771
C10: Short-term investments | D10: 84906 | E10: 1138174 | F10: 0 | G10: 0 | H10: 99603 | I10: 0 | J10: 0 | K10: 0 | L10: 0 | M10: 0 | N10: 0 | O10: 0 | P10: 0 | Q10: 0 | R10: 0
C11: Accounts receivable | D11: 276139 | E11: 183944 | F11: 422333 | G11: 346800 | H11: 360312 | I11: ='Income Statement'!I12*40/365 -> 363624.11 | J11: ='Income Statement'!J12*40/365 -> 424259.88 | K11: ='Income Statement'!K12*40/365 -> 483798.34 | L11: ='Income Statement'!L12*40/365 -> 549428.46 | M11: ='Income Statement'!M12*40/365 -> 621757.62 | N11: ='Income Statement'!N12*40/365 -> 701459.69 | O11: ='Income Statement'!O12*40/365 -> 789283.33 | P11: ='Income Statement'!P12*40/365 -> 886061.45 | ... R11: ='Income Statement'!R12*40/365 -> 1110300.4
C12: Current tax assets | D12: 4966 | E12: 1056 | F12: 974 | G12: 2579 | H12: 11974 | I12: =H12 -> 11974 | J12: =I12 -> 11974 | K12: =J12 -> 11974 | L12: =K12 -> 11974 | M12: =L12 -> 11974 | N12: =M12 -> 11974 | O12: =N12 -> 11974 | P12: =O12 -> 11974 | ... R12: =Q12 -> 11974
C13: Inventories | D13: 409521 | E13: 664698 | F13: 692261 | G13: 826863 | H13: 843989 | I13: ='Income Statement'!I19*125/365 -> 799600 | J13: ='Income Statement'!J19*125/365 -> 872297.23 | K13: ='Income Statement'!K19*125/365 -> 951847.32 | L13: ='Income Statement'!L19*125/365 -> 1038908.1 | M13: ='Income Statement'!M19*125/365 -> 1134201.3 | N13: ='Income Statement'!N19*125/365 -> 1238518.4 | O13: ='Income Statement'!O19*125/365 -> 1352727.8 | P13: ='Income Statement'!P19*125/365 -> 1477781.9 | ... R13: ='Income Statement'!R19*125/365 -> 1764706.1
C14: Supplies and prepaid expenses | D14: 95341 | E14: 157910 | F14: 149352 | G14: 145390 | H14: 169339 | I14: ='Income Statement'!I12*0.047 -> 155949.29 | J14: ='Income Statement'!J12*0.047 -> 181954.45 | K14: ='Income Statement'!K12*0.047 -> 207489.01 | L14: ='Income Statement'!L12*0.047 -> 235636.13 | M14: ='Income Statement'!M12*0.047 -> 266656.3 | N14: ='Income Statement'!N12*0.047 -> 300838.53 | O14: ='Income Statement'!O12*0.047 -> 338503.89 | P14: ='Income Statement'!P12*0.047 -> 380009.61 | ... R14: ='Income Statement'!R12*0.047 -> 476180.07
C15: Current portion of LT receivables, investments and other | D15: 23232 | E15: 32180 | F15: 10161 | G15: 1093 | H15: 39138 | I15: =H15 -> 39138 | J15: =I15 -> 39138 | K15: =J15 -> 39138 | L15: =K15 -> 39138 | M15: =L15 -> 39138 | N15: =M15 -> 39138 | O15: =N15 -> 39138 | P15: =O15 -> 39138 | ... R15: =Q15 -> 39138
C16: Total Current Assets | D16: 2141552 | E16: 3321636 | F16: 1841890 | G16: 1923187 | H16: 2639215 | I16: =SUM(I9:I15) -> 2998651.1 | J16: =SUM(J9:J15) -> 4083657.8 | K16: =SUM(K9:K15) -> 5409620.1 | L16: =SUM(L9:L15) -> 6994068.9 | M16: =SUM(M9:M15) -> 8869594.6 | N16: =SUM(N9:N15) -> 11066289 | O16: =SUM(O9:O15) -> 13605951 | P16: =SUM(P9:P15) -> 16532057 | ... R16: =SUM(R9:R15) -> 23702070
C18: Non-Current Assets
C19: Property, plant and equipment (PP&E) | D19: 3576599 | E19: 3473490 | F19: 3368772 | G19: 3286515 | H19: 3325077 | I19: =H19+I55-'Income Statement'!I18 -> 3415029 | J19: =I19+J55-'Income Statement'!J18 -> 3503739.6 | K19: =J19+K55-'Income Statement'!K18 -> 3590998 | L19: =K19+L55-'Income Statement'!L18 -> 3676578.4 | M19: =L19+M55-'Income Statement'!M18 -> 3760241.1 | N19: =M19+N55-'Income Statement'!N18 -> 3841730.1 | O19: =N19+O55-'Income Statement'!O18 -> 3920774.2 | P19: =O19+P55-'Income Statement'!P18 -> 3997083.9 | ... R19: =Q19+R55-'Income Statement'!R18 -> 4140251
C20: Intangible assets | D20: 51247 | E20: 47117 | F20: 43577 | G20: 39822 | H20: 36162 | I20: =MAX(0,H20-4000) -> 32162 | J20: =MAX(0,I20-4000) -> 28162 | K20: =MAX(0,J20-4000) -> 24162 | L20: =MAX(0,K20-4000) -> 20162 | M20: =MAX(0,L20-4000) -> 16162 | N20: =MAX(0,M20-4000) -> 12162 | O20: =MAX(0,N20-4000) -> 8162 | P20: =MAX(0,O20-4000) -> 4162 | ... R20: =MAX(0,Q20-4000) -> 0
C21: LT receivables, investments and other | D21: 577527 | E21: 595507 | F21: 613773 | G21: 595896 | H21: 647245 | I21: =H21 -> 647245 | J21: =I21 -> 647245 | K21: =J21 -> 647245 | L21: =K21 -> 647245 | M21: =L21 -> 647245 | N21: =M21 -> 647245 | O21: =N21 -> 647245 | P21: =O21 -> 647245 | ... R21: =Q21 -> 647245
C22: Investment in equity-accounted investees [incl. Westinghouse from 2023] | D22: 233240 | E22: 210972 | F22: 3173185 | G22: 3218456 | H22: 2987126 | I22: =H22+'Income Statement'!I36-I56 -> 2644378 | J22: =I22+'Income Statement'!J36-J56 -> 2267355.2 | K22: =J22+'Income Statement'!K36-K56 -> 1852630.1 | L22: =K22+'Income Statement'!L36-L56 -> 1422205.7 | M22: =L22+'Income Statement'!M36-M56 -> 955459.68 | N22: =M22+'Income Statement'!N36-N56 -> 449633.62 | O22: =N22+'Income Statement'!O36-O56 -> -59444.839 | P22: =O22+'Income Statement'!P36-P56 -> -597711.26 | ... R22: =Q22+'Income Statement'!R36-R56 -> -1758970.8
C23: Deferred tax assets | D23: 937579 | E23: 984071 | F23: 892860 | G23: 843131 | H23: 666457 | I23: =MAX(0,H23-40000) -> 626457 | J23: =MAX(0,I23-40000) -> 586457 | K23: =MAX(0,J23-40000) -> 546457 | L23: =MAX(0,K23-40000) -> 506457 | M23: =MAX(0,L23-40000) -> 466457 | N23: =MAX(0,M23-40000) -> 426457 | O23: =MAX(0,N23-40000) -> 386457 | P23: =MAX(0,O23-40000) -> 346457 | ... R23: =MAX(0,Q23-40000) -> 266457
C24: Total Non-Current Assets | D24: 5376192 | E24: 5311157 | F24: 8092167 | G24: 7983820 | H24: 7662067 | I24: =SUM(I19:I23) -> 7365271 | J24: =SUM(J19:J23) -> 7032958.8 | K24: =SUM(K19:K23) -> 6661492.1 | L24: =SUM(L19:L23) -> 6272648.1 | M24: =SUM(M19:M23) -> 5845564.7 | N24: =SUM(N19:N23) -> 5377227.7 | O24: =SUM(O19:O23) -> 4903193.4 | P24: =SUM(P19:P23) -> 4397236.7 | ... R24: =SUM(R19:R23) -> 3294982.3
C26: TOTAL ASSETS | D26: 7517744 | E26: 8632793 | F26: 9934057 | G26: 9907007 | H26: 10301282 | I26: =I16+I24 -> 10363922 | J26: =J16+J24 -> 11116617 | K26: =K16+K24 -> 12071112 | L26: =L16+L24 -> 13266717 | M26: =M16+M24 -> 14715159 | N26: =N16+N24 -> 16443516 | O26: =O16+O24 -> 18509144 | P26: =P16+P24 -> 20929294 | ... R26: =R16+R24 -> 26997052
C28: LIABILITIES
C29: Current Liabilities
C30: Accounts payable and accrued liabilities | D30: 340458 | E30: 374714 | F30: 577550 | G30: 619035 | H30: 871355 | I30: ='Income Statement'!I19*100/365 -> 639680 | J30: ='Income Statement'!J19*100/365 -> 697837.79 | K30: ='Income Statement'!K19*100/365 -> 761477.85 | L30: ='Income Statement'!L19*100/365 -> 831126.51 | M30: ='Income Statement'!M19*100/365 -> 907361.05 | N30: ='Income Statement'!N19*100/365 -> 990814.73 | O30: ='Income Statement'!O19*100/365 -> 1082182.2 | P30: ='Income Statement'!P19*100/365 -> 1182225.5 | ... R30: ='Income Statement'!R19*100/365 -> 1411764.9
C31: Current tax liabilities | D31: 4129 | E31: 6498 | F31: 24076 | G31: 21225 | H31: 16516 | I31: =H31 -> 16516 | J31: =I31 -> 16516 | K31: =J31 -> 16516 | L31: =K31 -> 16516 | M31: =L31 -> 16516 | N31: =M31 -> 16516 | O31: =N31 -> 16516 | P31: =O31 -> 16516 | ... R31: =Q31 -> 16516
C32: Current portion of long-term debt | D32: 0 | E32: 0 | F32: 499821 | G32: 285707 | H32: 0 | I32: 0 | J32: 0 | K32: 0 | L32: 0 | M32: 0 | N32: 0 | O32: 0 | P32: 0 | Q32: 0 | R32: 0
C33: Current portion of other liabilities | D33: 22791 | E33: 131324 | F33: 48544 | G33: 221820 | H33: 134667 | I33: =H33 -> 134667 | J33: =I33 -> 134667 | K33: =J33 -> 134667 | L33: =K33 -> 134667 | M33: =L33 -> 134667 | N33: =M33 -> 134667 | O33: =N33 -> 134667 | P33: =O33 -> 134667 | ... R33: =Q33 -> 134667
C34: Current portion of provisions | D34: 46365 | E34: 48305 | F34: 39113 | G34: 37974 | H34: 47648 | I34: =H34 -> 47648 | J34: =I34 -> 47648 | K34: =J34 -> 47648 | L34: =K34 -> 47648 | M34: =L34 -> 47648 | N34: =M34 -> 47648 | O34: =N34 -> 47648 | P34: =O34 -> 47648 | ... R34: =Q34 -> 47648
C35: Total Current Liabilities | D35: 413743 | E35: 560841 | F35: 1189104 | G35: 1185761 | H35: 1070186 | I35: =SUM(I30:I34) -> 838511 | J35: =SUM(J30:J34) -> 896668.79 | K35: =SUM(K30:K34) -> 960308.85 | L35: =SUM(L30:L34) -> 1029957.5 | M35: =SUM(M30:M34) -> 1106192.1 | N35: =SUM(N30:N34) -> 1189645.7 | O35: =SUM(O30:O34) -> 1281013.2 | P35: =SUM(P30:P34) -> 1381056.5 | ... R35: =SUM(R30:R34) -> 1610595.9
C37: Non-Current Liabilities
C38: Long-term debt | D38: 996250 | E38: 997000 | F38: 1284353 | G38: 995583 | H38: 996348 | I38: =H38 -> 996348 | J38: =I38 -> 996348 | K38: =J38 -> 996348 | L38: =K38 -> 996348 | M38: =L38 -> 996348 | N38: =M38 -> 996348 | O38: =N38 -> 996348 | P38: =O38 -> 996348 | ... R38: =Q38 -> 996348
C39: Other liabilities | D39: 171774 | E39: 216162 | F39: 343420 | G39: 363497 | H39: 377955 | I39: =H39+15000 -> 392955 | J39: =I39+15000 -> 407955 | K39: =J39+15000 -> 422955 | L39: =K39+15000 -> 437955 | M39: =L39+15000 -> 452955 | N39: =M39+15000 -> 467955 | O39: =N39+15000 -> 482955 | P39: =O39+15000 -> 497955 | ... R39: =Q39+15000 -> 527955
C40: Provisions (decommissioning and reclamation) | D40: 1090009 | E40: 1022725 | F40: 1022871 | G40: 997833 | H40: 953415 | I40: =MAX(0,H40-15000) -> 938415 | J40: =MAX(0,I40-15000) -> 923415 | K40: =MAX(0,J40-15000) -> 908415 | L40: =MAX(0,K40-15000) -> 893415 | M40: =MAX(0,L40-15000) -> 878415 | N40: =MAX(0,M40-15000) -> 863415 | O40: =MAX(0,N40-15000) -> 848415 | P40: =MAX(0,O40-15000) -> 833415 | ... R40: =MAX(0,Q40-15000) -> 803415
C41: Total Non-Current Liabilities | D41: 2258033 | E41: 2235887 | F41: 2650644 | G41: 2356913 | H41: 2327718 | I41: =SUM(I38:I40) -> 2327718 | J41: =SUM(J38:J40) -> 2327718 | K41: =SUM(K38:K40) -> 2327718 | L41: =SUM(L38:L40) -> 2327718 | M41: =SUM(M38:M40) -> 2327718 | N41: =SUM(N38:N40) -> 2327718 | O41: =SUM(O38:O40) -> 2327718 | P41: =SUM(P38:P40) -> 2327718 | ... R41: =SUM(R38:R40) -> 2327718
C43: TOTAL LIABILITIES | D43: 2671776 | E43: 2796728 | F43: 3839748 | G43: 3542674 | H43: 3397904 | I43: =I35+I41 -> 3166229 | J43: =J35+J41 -> 3224386.8 | K43: =K35+K41 -> 3288026.9 | L43: =L35+L41 -> 3357675.5 | M43: =M35+M41 -> 3433910.1 | N43: =N35+N41 -> 3517363.7 | O43: =O35+O41 -> 3608731.2 | P43: =P35+P41 -> 3708774.5 | ... R43: =R35+R41 -> 3938313.9
C45: SHAREHOLDERS' EQUITY
C46: Share capital | D46: 1903357 | E46: 2880336 | F46: 2914165 | G46: 2935367 | H46: 2938235 | I46: =H46 -> 2938235 | J46: =I46 -> 2938235 | K46: =J46 -> 2938235 | L46: =K46 -> 2938235 | M46: =L46 -> 2938235 | N46: =M46 -> 2938235 | O46: =N46 -> 2938235 | P46: =O46 -> 2938235 | ... R46: =Q46 -> 2938235
C47: Contributed surplus | D47: 230039 | E47: 224687 | F47: 215679 | G47: 210784 | H47: 211412 | I47: =H47 -> 211412 | J47: =I47 -> 211412 | K47: =J47 -> 211412 | L47: =K47 -> 211412 | M47: =L47 -> 211412 | N47: =M47 -> 211412 | O47: =N47 -> 211412 | P47: =O47 -> 211412 | ... R47: =Q47 -> 211412
C48: Retained earnings | D48: 2639650 | E48: 2696379 | F48: 2979743 | G48: 3099264 | H48: 3608778 | I48: =H48+'Income Statement'!I44-I57 -> 3903093.1 | J48: =I48+'Income Statement'!J44-J57 -> 4597629.8 | K48: =J48+'Income Statement'!K44-K57 -> 5488485.3 | L48: =K48+'Income Statement'!L44-L57 -> 6614441.5 | M48: =L48+'Income Statement'!M44-M57 -> 7986649.3 | N48: =M48+'Income Statement'!N44-N57 -> 9631552.8 | O48: =N48+'Income Statement'!O44-O57 -> 11605813 | P48: =O48+'Income Statement'!P44-P57 -> 13925920 | ... R48: =Q48+'Income Statement'!R44-R57 -> 19764138
C49: Other components of equity (AOCI / cash flow hedges) | D49: 72795 | E49: 34652 | F49: -15282 | G49: 118892 | H49: 144938 | I49: =H49 -> 144938 | J49: =I49 -> 144938 | K49: =J49 -> 144938 | L49: =K49 -> 144938 | M49: =L49 -> 144938 | N49: =M49 -> 144938 | O49: =N49 -> 144938 | P49: =O49 -> 144938 | ... R49: =Q49 -> 144938
...

Sheet Cash Flow
B2: CAMECO CORPORATION — CASH FLOW STATEMENT
B3: All figures in $CDN thousands | IFRS | Year ended December 31
C5: 2021A | D5: 2022A | E5: 2023A | F5: 2024A | G5: 2025A | H5: 2026AE | I5: 2027E | J5: 2028E | K5: 2029E | L5: 2030E | M5: 2031E | N5: 2032E | O5: 2033E | P5: 2034E | Q5: 2035E
B7: Operating Activities
B8: Net earnings (loss) | C8: -102654 | D8: 89264 | E8: 360816 | F8: 171842 | G8: 589542 | H8: ='2026 Interim'!E82*2 -> 311922 | I8: ='Income Statement'!J44 -> 694536.63 | J8: ='Income Statement'!K44 -> 890855.53 | K8: ='Income Statement'!L44 -> 1125956.2 | L8: ='Income Statement'!M44 -> 1372207.9 | M8: ='Income Statement'!N44 -> 1644903.4 | N8: ='Income Statement'!O44 -> 1974260.4 | O8: ='Income Statement'!P44 -> 2320106.4 | P8: ='Income Statement'!Q44 -> 2704899.7 | Q8: ='Income Statement'!R44 -> 3133318.8
B9: Adjustments — non-cash items:
B10: Depreciation and amortization | C10: 190415 | D10: 177376 | E10: 220324 | F10: 280702 | G10: 293094 | H10: ='2026 Interim'!E83*2 -> 278514 | I10: ='Income Statement'!J18 -> 290809.41 | J10: ='Income Statement'!K18 -> 303647.61 | K10: ='Income Statement'!L18 -> 317052.58 | L10: ='Income Statement'!M18 -> 331049.33 | M10: ='Income Statement'!N18 -> 345663.99 | N10: ='Income Statement'!O18 -> 360923.83 | O10: ='Income Statement'!P18 -> 376857.34 | P10: ='Income Statement'!Q18 -> 393494.26 | Q10: ='Income Statement'!R18 -> 410865.64
B11: Deferred charges and revenues | C11: 608 | D11: 43528 | E11: -21468 | F11: 61180 | G11: -24747 | H11: ='2026 Interim'!E84*2 -> -12252 | I11: 0 | J11: 0 | K11: 0 | L11: 0 | M11: 0 | N11: 0 | O11: 0 | P11: 0 | Q11: 0
B12: Unrealized loss (gain) on derivatives | C12: 13771 | D12: 82636 | E12: -61658 | F12: 149629 | G12: -145751 | H12: ='2026 Interim'!E85*2 -> 194904 | I12: 0 | J12: 0 | K12: 0 | L12: 0 | M12: 0 | N12: 0 | O12: 0 | P12: 0 | Q12: 0
B13: Share-based compensation | C13: 4536 | D13: 3318 | E13: 3692 | F13: 6775 | G13: 9656 | H13: ='2026 Interim'!E86*2 -> 11594 | I13: 12000 | J13: 12000 | K13: 12000 | L13: 12000 | M13: 12000 | N13: 12000 | O13: 12000 | P13: 12000 | Q13: 12000
B14: Loss on disposal of assets | C14: 3803 | D14: 514 | E14: 2188 | F14: 1042 | G14: 3117 | H14: ='2026 Interim'!E87*2 -> 1986 | I14: ='Income Statement'!J28 -> 3935.4048 | J14: ='Income Statement'!K28 -> 4487.6794 | K14: ='Income Statement'!L28 -> 5096.4598 | L14: ='Income Statement'!M28 -> 5767.38 | M14: ='Income Statement'!N28 -> 6506.6908 | N14: ='Income Statement'!O28 -> 7321.3367 | O14: ='Income Statement'!P28 -> 8219.0438 | P14: ='Income Statement'!Q28 -> 9208.4198 | Q14: ='Income Statement'!R28 -> 10299.068
B15: Finance costs | C15: 76612 | D15: 85728 | E15: 115869 | F15: 147171 | G15: 115175 | H15: ='2026 Interim'!E88*2 -> 115002 | I15: =-'Income Statement'!J33 -> 108101.88 | J15: =-'Income Statement'!K33 -> 101615.77 | K15: =-'Income Statement'!L33 -> 95518.821 | L15: =-'Income Statement'!M33 -> 89787.692 | M15: =-'Income Statement'!N33 -> 84400.43 | N15: =-'Income Statement'!O33 -> 79336.405 | O15: =-'Income Statement'!P33 -> 74576.22 | P15: =-'Income Statement'!Q33 -> 70101.647 | Q15: =-'Income Statement'!R33 -> 65895.548
B16: Finance income | C16: -6804 | D16: -37499 | E16: -111670 | F16: -21228 | G16: -23172 | H16: ='2026 Interim'!E89*2 -> -35698 | I16: =-'Income Statement'!J35 -> 0 | J16: =-'Income Statement'!K35 -> 0 | K16: =-'Income Statement'!L35 -> 0 | L16: =-'Income Statement'!M35 -> 0 | M16: =-'Income Statement'!N35 -> 0 | N16: =-'Income Statement'!O35 -> 0 | O16: =-'Income Statement'!P35 -> 0 | P16: =-'Income Statement'!Q35 -> 0 | Q16: =-'Income Statement'!R35 -> 0
B17: Share of equity-accounted investee earnings (loss) | C17: -68283 | D17: -93988 | E17: -154462 | F17: 10844 | G17: -216386 | H17: ='2026 Interim'!E90*2 -> -148952 | I17: =-'Income Statement'!J36 -> -163847.2 | J17: =-'Income Statement'!K36 -> -180231.92 | K17: =-'Income Statement'!L36 -> -224028.28 | L17: =-'Income Statement'!M36 -> -253151.95 | M17: =-'Income Statement'!N36 -> -286061.71 | N17: =-'Income Statement'!O36 -> -361998.09 | O17: =-'Income Statement'!P36 -> -419917.78 | P17: =-'Income Statement'!Q36 -> -487104.63 | Q17: =-'Income Statement'!R36 -> -565041.37
B18: Other income | C18: -446 | D18: -96934 | E18: -16238 | F18: -307 | G18: -1460 | H18: ='2026 Interim'!E93*2 -> -1520 | I18: =-'Income Statement'!J38 -> 0 | J18: =-'Income Statement'!K38 -> 0 | K18: =-'Income Statement'!L38 -> 0 | L18: =-'Income Statement'!M38 -> 0 | M18: =-'Income Statement'!N38 -> 0 | N18: =-'Income Statement'!O38 -> 0 | O18: =-'Income Statement'!P38 -> 0 | P18: =-'Income Statement'!Q38 -> 0 | Q18: =-'Income Statement'!R38 -> 0
B19: Foreign exchange (gains) losses [2024+ separately disclosed] | C19: 0 | D19: 0 | E19: 0 | F19: -65517 | G19: 61740 | H19: ='2026 Interim'!E91*2 -> -54620 | I19: 0 | J19: 0 | K19: 0 | L19: 0 | M19: 0 | N19: 0 | O19: 0 | P19: 0 | Q19: 0
B20: Other operating expense (income) | C20: -8407 | D20: 22944 | E20: -7509 | F20: -37683 | G20: -28333 | H20: ='2026 Interim'!E92*2 -> 7592 | I20: 0 | J20: 0 | K20: 0 | L20: 0 | M20: 0 | N20: 0 | O20: 0 | P20: 0 | Q20: 0
B21: Income tax expense (recovery) | C21: -1201 | D21: -4469 | E21: 126337 | F21: 84874 | G21: 187719 | H21: ='2026 Interim'!E94*2 -> 105736 | I21: 0 | J21: 0 | K21: 0 | L21: 0 | M21: 0 | N21: 0 | O21: 0 | P21: 0 | Q21: 0
B23: Working capital and other:
B24: Interest received | C24: 9374 | D24: 35443 | E24: 113797 | F24: 21228 | G24: 23172 | H24: ='2026 Interim'!E95*2 -> 36560 | I24: ='Income Statement'!J35 -> 0 | J24: ='Income Statement'!K35 -> 0 | K24: ='Income Statement'!L35 -> 0 | L24: ='Income Statement'!M35 -> 0 | M24: ='Income Statement'!N35 -> 0 | N24: ='Income Statement'!O35 -> 0 | O24: ='Income Statement'!P35 -> 0 | P24: ='Income Statement'!Q35 -> 0 | Q24: ='Income Statement'!R35 -> 0
B25: Income taxes received (paid) | C25: 9583 | D25: -1521 | E25: 70372 | F25: -38486 | G25: -90206 | H25: ='2026 Interim'!E96*2 -> -473816 | I25: 0 | J25: 0 | K25: 0 | L25: 0 | M25: 0 | N25: 0 | O25: 0 | P25: 0 | Q25: 0
B26: Dividends from equity-accounted investees | C26: 50128 | D26: 117698 | E26: 113642 | F26: 185447 | G26: 446749 | H26: ='2026 Interim'!E97*2 -> 492118 | I26: ='Balance Sheet'!J56 -> 540870 | J26: ='Balance Sheet'!K56 -> 594957 | K26: ='Balance Sheet'!L56 -> 654452.7 | L26: ='Balance Sheet'!M56 -> 719897.97 | M26: ='Balance Sheet'!N56 -> 791887.77 | N26: ='Balance Sheet'!O56 -> 871076.54 | O26: ='Balance Sheet'!P56 -> 958184.2 | P26: ='Balance Sheet'!Q56 -> 1054002.6 | Q26: ='Balance Sheet'!R56 -> 1159402.9
B27: Other operating items (working capital changes) | C27: 287253 | D27: -119431 | E27: -65896 | F27: -52225 | G27: 208523 | H27: =('2026 Interim'!E98+'2026 Interim'!E99)*2 -> -611556 | I27: =-('Balance Sheet'!J11-'Balance Sheet'!I11)-('Balance Sheet'!J13-'Balance Sheet'!I13)-('Balance Sheet'!J14-'Balance Sheet'!I14)+('Balance Sheet'!J30-'Balance Sheet'!I30) -> -101180.38 | J27: =-('Balance Sheet'!K11-'Balance Sheet'!J11)-('Balance Sheet'!K13-'Balance Sheet'!J13)-('Balance Sheet'!K14-'Balance Sheet'!J14)+('Balance Sheet'!K30-'Balance Sheet'!J30) -> -100983.03 | K27: =-('Balance Sheet'!L11-'Balance Sheet'!K11)-('Balance Sheet'!L13-'Balance Sheet'!K13)-('Balance Sheet'!L14-'Balance Sheet'!K14)+('Balance Sheet'!L30-'Balance Sheet'!K30) -> -111189.4 | L27: =-('Balance Sheet'!M11-'Balance Sheet'!L11)-('Balance Sheet'!M13-'Balance Sheet'!L13)-('Balance Sheet'!M14-'Balance Sheet'!L14)+('Balance Sheet'!M30-'Balance Sheet'!L30) -> -122407.97 | M27: =-('Balance Sheet'!N11-'Balance Sheet'!M11)-('Balance Sheet'!N13-'Balance Sheet'!M13)-('Balance Sheet'!N14-'Balance Sheet'!M14)+('Balance Sheet'!N30-'Balance Sheet'!M30) -> -134747.72 | N27: =-('Balance Sheet'!O11-'Balance Sheet'!N11)-('Balance Sheet'!O13-'Balance Sheet'!N13)-('Balance Sheet'!O14-'Balance Sheet'!N14)+('Balance Sheet'!O30-'Balance Sheet'!N30) -> -148330.87 | O27: =-('Balance Sheet'!P11-'Balance Sheet'!O11)-('Balance Sheet'!P13-'Balance Sheet'!O13)-('Balance Sheet'!P14-'Balance Sheet'!O14)+('Balance Sheet'!P30-'Balance Sheet'!O30) -> -163294.67 | P27: =-('Balance Sheet'!Q11-'Balance Sheet'!P11)-('Balance Sheet'!Q13-'Balance Sheet'!P13)-('Balance Sheet'!Q14-'Balance Sheet'!P14)+('Balance Sheet'!Q30-'Balance Sheet'!P30) -> -179793.41 | Q27: =-('Balance Sheet'!R11-'Balance Sheet'!Q11)-('Balance Sheet'!R13-'Balance Sheet'!Q13)-('Balance Sheet'!R14-'Balance Sheet'!Q14)+('Balance Sheet'!R30-'Balance Sheet'!Q30) -> -198000.81
B29: Net Cash from Operating Activities | C29: 458288 | D29: 304607 | E29: 688136 | F29: 905288 | G29: 1408432 | H29: ='Cash Flow'!H8+'Cash Flow'!H10+'Cash Flow'!H11+'Cash Flow'!H12+'Cash Flow'!H13+'Cash Flow'!H14+'Cash Flow'!H15+'Cash Flow'!H16+'Cash Flow'!H17+'Cash Flow'!H18+'Cash Flow'!H19+'Cash Flow'!H20+'Cash Flow'!H21+'Cash Flow'!H24+'Cash Flow'!H25+'Cash Flow'!H26+'Cash Flow'!H27 -> 217514 | I29: ='Cash Flow'!I8+'Cash Flow'!I10+'Cash Flow'!I11+'Cash Flow'!I12+'Cash Flow'!I13+'Cash Flow'!I14+'Cash Flow'!I15+'Cash Flow'!I16+'Cash Flow'!I17+'Cash Flow'!I18+'Cash Flow'!I19+'Cash Flow'!I20+'Cash Flow'!I21+'Cash Flow'!I24+'Cash Flow'!I25+'Cash Flow'!I26+'Cash Flow'!I27 -> 1385225.7 | J29: ='Cash Flow'!J8+'Cash Flow'!J10+'Cash Flow'!J11+'Cash Flow'!J12+'Cash Flow'!J13+'Cash Flow'!J14+'Cash Flow'!J15+'Cash Flow'!J16+'Cash Flow'!J17+'Cash Flow'!J18+'Cash Flow'!J19+'Cash Flow'!J20+'Cash Flow'!J21+'Cash Flow'!J24+'Cash Flow'!J25+'Cash Flow'!J26+'Cash Flow'!J27 -> 1626348.6 | K29: ='Cash Flow'!K8+'Cash Flow'!K10+'Cash Flow'!K11+'Cash Flow'!K12+'Cash Flow'!K13+'Cash Flow'!K14+'Cash Flow'!K15+'Cash Flow'!K16+'Cash Flow'!K17+'Cash Flow'!K18+'Cash Flow'!K19+'Cash Flow'!K20+'Cash Flow'!K21+'Cash Flow'!K24+'Cash Flow'!K25+'Cash Flow'!K26+'Cash Flow'!K27 -> 1874859 | L29: ='Cash Flow'!L8+'Cash Flow'!L10+'Cash Flow'!L11+'Cash Flow'!L12+'Cash Flow'!L13+'Cash Flow'!L14+'Cash Flow'!L15+'Cash Flow'!L16+'Cash Flow'!L17+'Cash Flow'!L18+'Cash Flow'!L19+'Cash Flow'!L20+'Cash Flow'!L21+'Cash Flow'!L24+'Cash Flow'!L25+'Cash Flow'!L26+'Cash Flow'!L27 -> 2155150.3 | M29: ='Cash Flow'!M8+'Cash Flow'!M10+'Cash Flow'!M11+'Cash Flow'!M12+'Cash Flow'!M13+'Cash Flow'!M14+'Cash Flow'!M15+'Cash Flow'!M16+'Cash Flow'!M17+'Cash Flow'!M18+'Cash Flow'!M19+'Cash Flow'!M20+'Cash Flow'!M21+'Cash Flow'!M24+'Cash Flow'!M25+'Cash Flow'!M26+'Cash Flow'!M27 -> 2464552.9 | N29: ='Cash Flow'!N8+'Cash Flow'!N10+'Cash Flow'!N11+'Cash Flow'!N12+'Cash Flow'!N13+'Cash Flow'!N14+'Cash Flow'!N15+'Cash Flow'!N16+'Cash Flow'!N17+'Cash Flow'!N18+'Cash Flow'!N19+'Cash Flow'!N20+'Cash Flow'!N21+'Cash Flow'!N24+'Cash Flow'!N25+'Cash Flow'!N26+'Cash Flow'!N27 -> 2794589.6 | O29: ='Cash Flow'!O8+'Cash Flow'!O10+'Cash Flow'!O11+'Cash Flow'!O12+'Cash Flow'!O13+'Cash Flow'!O14+'Cash Flow'!O15+'Cash Flow'!O16+'Cash Flow'!O17+'Cash Flow'!O18+'Cash Flow'!O19+'Cash Flow'!O20+'Cash Flow'!O21+'Cash Flow'!O24+'Cash Flow'!O25+'Cash Flow'!O26+'Cash Flow'!O27 -> 3166730.8 | ... Q29: ='Cash Flow'!Q8+'Cash Flow'!Q10+'Cash Flow'!Q11+'Cash Flow'!Q12+'Cash Flow'!Q13+'Cash Flow'!Q14+'Cash Flow'!Q15+'Cash Flow'!Q16+'Cash Flow'!Q17+'Cash Flow'!Q18+'Cash Flow'!Q19+'Cash Flow'!Q20+'Cash Flow'!Q21+'Cash Flow'!Q24+'Cash Flow'!Q25+'Cash Flow'!Q26+'Cash Flow'!Q27 -> 4028739.7
B31: Investing Activities
B32: Capital expenditures — additions to PP&E | C32: -98784 | D32: -143448 | E32: -153631 | F32: -211635 | G32: -333025 | H32: ='2026 Interim'!E102*2 -> -368466 | I32: =-'Balance Sheet'!J55 -> -379520 | J32: =-'Balance Sheet'!K55 -> -390906 | K32: =-'Balance Sheet'!L55 -> -402633 | L32: =-'Balance Sheet'!M55 -> -414712 | M32: =-'Balance Sheet'!N55 -> -427153 | N32: =-'Balance Sheet'!O55 -> -439968 | O32: =-'Balance Sheet'!P55 -> -453167 | P32: =-'Balance Sheet'!Q55 -> -466762 | Q32: =-'Balance Sheet'!R55 -> -480765
B33: Acquisitions (net of cash) [2023: Westinghouse $3.0B] | C33: 0 | D33: -101681 | E33: -3028977 | F33: 0 | G33: 0 | H33: 0 | I33: 0 | J33: 0 | K33: 0 | L33: 0 | M33: 0 | N33: 0 | O33: 0 | P33: 0 | Q33: 0
B34: (Increase) decrease in short-term investments | C34: -59921 | D34: -1044473 | E34: 1136687 | F34: 0 | G34: -99603 | H34: ='2026 Interim'!E103*2 -> 199206 | I34: 0 | J34: 0 | K34: 0 | L34: 0 | M34: 0 | N34: 0 | O34: 0 | P34: 0 | Q34: 0
B35: Decrease (increase) in LT receivables and other | C35: 73050 | D35: -2000 | E35: 1000 | F35: 4816 | G35: -1137 | H35: ='2026 Interim'!E104*2 -> 0 | I35: 0 | J35: 0 | K35: 0 | L35: 0 | M35: 0 | N35: 0 | O35: 0 | P35: 0 | Q35: 0
B36: Proceeds from disposal of PP&E | C36: 5357 | D36: 780 | E36: 69 | F36: 377 | G36: 245 | H36: ='2026 Interim'!E105*2 -> 282 | I36: 0 | J36: 0 | K36: 0 | L36: 0 | M36: 0 | N36: 0 | O36: 0 | P36: 0 | Q36: 0
B38: Net Cash Used in Investing Activities | C38: -80298 | D38: -1290822 | E38: -2044852 | F38: -206442 | G38: -433520 | H38: ='Cash Flow'!H32+'Cash Flow'!H33+'Cash Flow'!H34+'Cash Flow'!H35+'Cash Flow'!H36 -> -168978 | I38: ='Cash Flow'!I32+'Cash Flow'!I33+'Cash Flow'!I34+'Cash Flow'!I35+'Cash Flow'!I36 -> -379520 | J38: ='Cash Flow'!J32+'Cash Flow'!J33+'Cash Flow'!J34+'Cash Flow'!J35+'Cash Flow'!J36 -> -390906 | K38: ='Cash Flow'!K32+'Cash Flow'!K33+'Cash Flow'!K34+'Cash Flow'!K35+'Cash Flow'!K36 -> -402633 | L38: ='Cash Flow'!L32+'Cash Flow'!L33+'Cash Flow'!L34+'Cash Flow'!L35+'Cash Flow'!L36 -> -414712 | M38: ='Cash Flow'!M32+'Cash Flow'!M33+'Cash Flow'!M34+'Cash Flow'!M35+'Cash Flow'!M36 -> -427153 | N38: ='Cash Flow'!N32+'Cash Flow'!N33+'Cash Flow'!N34+'Cash Flow'!N35+'Cash Flow'!N36 -> -439968 | O38: ='Cash Flow'!O32+'Cash Flow'!O33+'Cash Flow'!O34+'Cash Flow'!O35+'Cash Flow'!O36 -> -453167 | ... Q38: ='Cash Flow'!Q32+'Cash Flow'!Q33+'Cash Flow'!Q34+'Cash Flow'!Q35+'Cash Flow'!Q36 -> -480765
B40: Financing Activities
B41: Increase in long-term debt | C41: 0 | D41: 0 | E41: 816582 | F41: 497022 | G41: 0 | H41: 0 | I41: 0 | J41: 0 | K41: 0 | L41: 0 | M41: 0 | N41: 0 | O41: 0 | P41: 0 | Q41: 0
B42: Decrease in long-term debt | C42: 0 | D42: 0 | E42: 0 | F42: -1041590 | G42: -285240 | H42: ='2026 Interim'!E108*2 -> 0 | I42: 0 | J42: 0 | K42: 0 | L42: 0 | M42: 0 | N42: 0 | O42: 0 | P42: 0 | Q42: 0
B43: Interest paid | C43: -38977 | D43: -38856 | E43: -40798 | F43: -88818 | G43: -52642 | H43: ='2026 Interim'!E109*2 -> -52652 | I43: ='Income Statement'!J33*0.46 -> -49726.865 | J43: ='Income Statement'!K33*0.46 -> -46743.253 | K43: ='Income Statement'!L33*0.46 -> -43938.658 | L43: ='Income Statement'!M33*0.46 -> -41302.338 | M43: ='Income Statement'!N33*0.46 -> -38824.198 | N43: ='Income Statement'!O33*0.46 -> -36494.746 | O43: ='Income Statement'!P33*0.46 -> -34305.061 | P43: ='Income Statement'!Q33*0.46 -> -32246.758 | Q43: ='Income Statement'!R33*0.46 -> -30311.952
B44: Proceeds from share issuance (stock options) | C44: 26771 | D44: 9632 | E44: 27537 | F44: 16656 | G44: 2170 | H44: ='2026 Interim'!E111*2 -> 2292 | I44: 2000 | J44: 2000 | K44: 2000 | L44: 2000 | M44: 2000 | N44: 2000 | O44: 2000 | P44: 2000 | Q44: 2000
B45: Proceeds from share issuance (net of costs) | C45: 0 | D45: 953285 | E45: 0 | F45: 0 | G45: 0 | H45: 0 | I45: 0 | J45: 0 | K45: 0 | L45: 0 | M45: 0 | N45: 0 | O45: 0 | P45: 0 | Q45: 0
B46: Lease principal payments | C46: -2727 | D46: -2908 | E46: -2430 | F46: -2051 | G46: -2733 | H46: ='2026 Interim'!E110*2 -> -3812 | I46: -3000 | J46: -3000 | K46: -3000 | L46: -3000 | M46: -3000 | N46: -3000 | O46: -3000 | P46: -3000 | Q46: -3000
B47: Dividends paid | C47: -31839 | D47: -51895 | E47: -52079 | F47: -69641 | G47: -104480 | H47: ='2026 Interim'!E112*2 -> 0 | I47: -126000 | J47: -132300 | K47: -138915 | L47: -145861 | M47: -153154 | N47: -160812 | O47: -168852 | P47: -177295 | Q47: -186160
B49: Net Cash from (Used in) Financing Activities | C49: -46772 | D49: 869258 | E49: 748812 | F49: -688422 | G49: -442925 | H49: ='Cash Flow'!H41+'Cash Flow'!H42+'Cash Flow'!H43+'Cash Flow'!H44+'Cash Flow'!H45+'Cash Flow'!H46+'Cash Flow'!H47 -> -54172 | I49: ='Cash Flow'!I41+'Cash Flow'!I42+'Cash Flow'!I43+'Cash Flow'!I44+'Cash Flow'!I45+'Cash Flow'!I46+'Cash Flow'!I47 -> -176726.86 | J49: ='Cash Flow'!J41+'Cash Flow'!J42+'Cash Flow'!J43+'Cash Flow'!J44+'Cash Flow'!J45+'Cash Flow'!J46+'Cash Flow'!J47 -> -180043.25 | K49: ='Cash Flow'!K41+'Cash Flow'!K42+'Cash Flow'!K43+'Cash Flow'!K44+'Cash Flow'!K45+'Cash Flow'!K46+'Cash Flow'!K47 -> -183853.66 | L49: ='Cash Flow'!L41+'Cash Flow'!L42+'Cash Flow'!L43+'Cash Flow'!L44+'Cash Flow'!L45+'Cash Flow'!L46+'Cash Flow'!L47 -> -188163.34 | M49: ='Cash Flow'!M41+'Cash Flow'!M42+'Cash Flow'!M43+'Cash Flow'!M44+'Cash Flow'!M45+'Cash Flow'!M46+'Cash Flow'!M47 -> -192978.2 | N49: ='Cash Flow'!N41+'Cash Flow'!N42+'Cash Flow'!N43+'Cash Flow'!N44+'Cash Flow'!N45+'Cash Flow'!N46+'Cash Flow'!N47 -> -198306.75 | O49: ='Cash Flow'!O41+'Cash Flow'!O42+'Cash Flow'!O43+'Cash Flow'!O44+'Cash Flow'!O45+'Cash Flow'!O46+'Cash Flow'!O47 -> -204157.06 | ... Q49: ='Cash Flow'!Q41+'Cash Flow'!Q42+'Cash Flow'!Q43+'Cash Flow'!Q44+'Cash Flow'!Q45+'Cash Flow'!Q46+'Cash Flow'!Q47 -> -217471.95
...

Sheet DCF
C2: CAMECO CORPORATION — DISCOUNTED CASH FLOW VALUATION
C3: Unlevered DCF | USD/CDN @ 1.40 | All figures $CDN thousands unless noted
C5: I. WACC CALCULATION
C6: Risk-Free Rate (Canadian 10Y Gov't Bond) | D6: 0.037
C7: Equity Risk Premium (Damodaran, Canada 2025) | D7: 0.055
C8: Beta (5Y Monthly vs. TSX — Cameco) | D8: =CHOOSE(Cover!C17,DCF!D82,DCF!E82) -> 1
C9: Cost of Equity (CAPM: Rf + β × ERP) | D9: =D6+D8*D7 -> 0.092
C11: Pre-Tax Cost of Debt (blended coupon rate) | D11: 0.049
C12: Tax Rate (effective, normalized) | D12: 0.29
C13: After-Tax Cost of Debt | D13: =D11*(1-D12) -> 0.03479
C14: Market Cap (CDN$B, for Wd) ← input at current price | D14: 60.6 | E14: 435.5M sh × CDN$139.11 (update when price moves materially)
C15: Debt Weight [Total Debt / (Debt + Mkt Cap)] | D15: =(-D57)/(-D57+D14*1000000) -> 0.016175439
C16: Equity Weight | D16: =1-D15 -> 0.98382456
C18: WACC | D18: =D9*D16+D13*D15 -> 0.091074603
C19: ↑ Change blue cells (Rf, ERP, β, Kd, Wd) to override WACC
E20: 2027E | F20: 2028E | G20: 2029E | H20: 2030E | I20: 2031E | J20: 2032E | K20: 2033E | L20: 2034E | M20: 2035E
C22: II. UNLEVERED FREE CASH FLOW BRIDGE ($CDN thousands)
C23: EBIT (← Income Statement row 30) | E23: ='Income Statement'!J30 -> 929379.34 | F23: ='Income Statement'!K30 -> 1184965.5 | G23: ='Income Statement'!L30 -> 1468536.9 | H23: ='Income Statement'!M30 -> 1782963.3 | I23: ='Income Statement'!N30 -> 2131455.3 | J23: ='Income Statement'!O30 -> 2517612 | K23: ='Income Statement'!P30 -> 2945477 | L23: ='Income Statement'!Q30 -> 3419603 | M23: ='Income Statement'!R30 -> 3945126
C24: (×) Tax effect @ normalized rate | E24: =-D12*E23 -> -269520.01 | F24: =-D12*F23 -> -343640 | G24: =-D12*G23 -> -425875.7 | H24: =-D12*H23 -> -517059.37 | I24: =-D12*I23 -> -618122.04 | J24: =-D12*J23 -> -730107.48 | K24: =-D12*K23 -> -854188.33 | L24: =-D12*L23 -> -991684.86 | M24: =-D12*M23 -> -1144086.5
C25: NOPAT = EBIT × (1 − t) | E25: =(1-D12)*E23 -> 659859.33 | F25: =(1-D12)*F23 -> 841325.52 | G25: =(1-D12)*G23 -> 1042661.2 | H25: =(1-D12)*H23 -> 1265904 | I25: =(1-D12)*I23 -> 1513333.3 | J25: =(1-D12)*J23 -> 1787504.5 | K25: =(1-D12)*K23 -> 2091288.7 | L25: =(1-D12)*L23 -> 2427918.1 | M25: =(1-D12)*M23 -> 2801039.5
C27: (+) Depreciation & Amortization | E27: ='Cash Flow'!I10 -> 290809.41 | F27: ='Cash Flow'!J10 -> 303647.61 | G27: ='Cash Flow'!K10 -> 317052.58 | H27: ='Cash Flow'!L10 -> 331049.33 | I27: ='Cash Flow'!M10 -> 345663.99 | J27: ='Cash Flow'!N10 -> 360923.83 | K27: ='Cash Flow'!O10 -> 376857.34 | L27: ='Cash Flow'!P10 -> 393494.26 | M27: ='Cash Flow'!Q10 -> 410865.64
C28: (+) Dividends from Equity Investees (Westinghouse 49%) | D28: WH pays ~$492M/yr; excluded from EBIT (equity-accounted) | E28: ='Cash Flow'!I26 -> 540870 | F28: ='Cash Flow'!J26 -> 594957 | G28: ='Cash Flow'!K26 -> 654452.7 | H28: ='Cash Flow'!L26 -> 719897.97 | I28: ='Cash Flow'!M26 -> 791887.77 | J28: ='Cash Flow'!N26 -> 871076.54 | K28: ='Cash Flow'!O26 -> 958184.2 | L28: ='Cash Flow'!P26 -> 1054002.6 | M28: ='Cash Flow'!Q26 -> 1159402.9
C29: (+/−) Change in Working Capital | E29: ='Cash Flow'!I27 -> -101180.38 | F29: ='Cash Flow'!J27 -> -100983.03 | G29: ='Cash Flow'!K27 -> -111189.4 | H29: ='Cash Flow'!L27 -> -122407.97 | I29: ='Cash Flow'!M27 -> -134747.72 | J29: ='Cash Flow'!N27 -> -148330.87 | K29: ='Cash Flow'!O27 -> -163294.67 | L29: ='Cash Flow'!P27 -> -179793.41 | M29: ='Cash Flow'!Q27 -> -198000.81
C30: (−) Capital Expenditures | E30: ='Cash Flow'!I32 -> -379520 | F30: ='Cash Flow'!J32 -> -390906 | G30: ='Cash Flow'!K32 -> -402633 | H30: ='Cash Flow'!L32 -> -414712 | I30: ='Cash Flow'!M32 -> -427153 | J30: ='Cash Flow'!N32 -> -439968 | K30: ='Cash Flow'!O32 -> -453167 | L30: ='Cash Flow'!P32 -> -466762 | M30: ='Cash Flow'!Q32 -> -480765
C32: Unlevered Free Cash Flow | E32: =E25+E27+E28+E29+E30 -> 1010838.4 | F32: =F25+F27+F28+F29+F30 -> 1248041.1 | G32: =G25+G27+G28+G29+G30 -> 1500344.1 | H32: =H25+H27+H28+H29+H30 -> 1779731.3 | I32: =I25+I27+I28+I29+I30 -> 2088984.3 | J32: =J25+J27+J28+J29+J30 -> 2431206 | K32: =K25+K27+K28+K29+K30 -> 2809868.5 | L32: =L25+L27+L28+L29+L30 -> 3228859.6 | M32: =M25+M27+M28+M29+M30 -> 3692542.2
C35: III. DCF CALCULATION
C36: Year Number | E36: 1 | F36: 2 | G36: 3 | H36: 4 | I36: 5 | J36: 6 | K36: 7 | L36: 8 | M36: 9
C37: Discount Period (mid-year) | E37: 0.5 | F37: 1.5 | G37: 2.5 | H37: 3.5 | I37: 4.5 | J37: 5.5 | K37: 6.5 | L37: 7.5 | M37: 8.5
C38: Discount Factor | E38: =1/(1+$D$18)^E37 -> 0.95735449 | F38: =1/(1+$D$18)^F37 -> 0.87744182 | G38: =1/(1+$D$18)^G37 -> 0.80419966 | H38: =1/(1+$D$18)^H37 -> 0.73707119 | I38: =1/(1+$D$18)^I37 -> 0.6755461 | J38: =1/(1+$D$18)^J37 -> 0.61915665 | K38: =1/(1+$D$18)^K37 -> 0.56747417 | L38: =1/(1+$D$18)^L37 -> 0.52010574 | M38: =1/(1+$D$18)^M37 -> 0.47669127
C39: PV of UFCF | E39: =E32*E38 -> 967730.64 | F39: =F32*F38 -> 1095083.5 | G39: =G32*G38 -> 1206576.2 | H39: =H32*H38 -> 1311788.7 | I39: =I32*I38 -> 1411205.2 | J39: =J32*J38 -> 1505297.4 | K39: =K32*K38 -> 1594527.8 | L39: =L32*L38 -> 1679348.4 | M39: =M32*M38 -> 1760202.6
C43: IV. TERMINAL VALUE
C44: Terminal Growth Rate (g) | D44: =CHOOSE(Cover!C17,DCF!D81,DCF!E81) -> 0.03
C45: Terminal Year UFCF (= 2035E) | D45: =M32 -> 3692542.2
C46: Terminal Value = UFCF × (1+g) / (WACC − g) | D46: =D45*(1+D44)/(D18-D44) -> 62273322
C47: Discount Factor (end of year 9) | D47: =1/(1+D18)^9 -> 0.45636253
C48: PV of Terminal Value | D48: =D46*D47 -> 28419211
C51: V. ENTERPRISE VALUE BRIDGE ($CDN thousands)
C52: Sum of PV(UFCF) 2027E – 2035E | D52: =SUM(E39:M39) -> 12531760
C53: (+) PV of Terminal Value | D53: =D48 -> 28419211
C54: Enterprise Value | D54: =D52+D53 -> 40950971
...

Sheet Uranium Spot Rate
B2: CAMECO CORPORATION — UPSIDE CASE ASSUMPTIONS
B3: Uranium Segment | Price × Volume drivers | All figures in $CDN thousands | IFRS
B5: URANIUM SEGMENT — UPSIDE PROJECTIONS
C6: 2024A | D6: 2025A | E6: H1 2026A | F6: 2026E | G6: 2027E | H6: 2028E | I6: 2029E | J6: 2030E | K6: 2031E | L6: 2032E | M6: 2033E | N6: 2034E | O6: 2035E
B8: Sales Volume (M lbs U3O8) | C8: 33.6 | D8: 33 | E8: 14.9 | F8: 30 | G8: =$F8 + ($O8-$F8) * (COLUMN()-COLUMN($F8)) / (COLUMN($O8)-COLUMN($F8)) -> 32.466667 | H8: =$F8 + ($O8-$F8) * (COLUMN()-COLUMN($F8)) / (COLUMN($O8)-COLUMN($F8)) -> 34.933333 | I8: =$F8 + ($O8-$F8) * (COLUMN()-COLUMN($F8)) / (COLUMN($O8)-COLUMN($F8)) -> 37.4 | J8: =$F8 + ($O8-$F8) * (COLUMN()-COLUMN($F8)) / (COLUMN($O8)-COLUMN($F8)) -> 39.866667 | K8: =$F8 + ($O8-$F8) * (COLUMN()-COLUMN($F8)) / (COLUMN($O8)-COLUMN($F8)) -> 42.333333 | L8: =$F8 + ($O8-$F8) * (COLUMN()-COLUMN($F8)) / (COLUMN($O8)-COLUMN($F8)) -> 44.8 | M8: =$F8 + ($O8-$F8) * (COLUMN()-COLUMN($F8)) / (COLUMN($O8)-COLUMN($F8)) -> 47.266667 | N8: =$F8 + ($O8-$F8) * (COLUMN()-COLUMN($F8)) / (COLUMN($O8)-COLUMN($F8)) -> 49.733333 | O8: =C26 -> 52.2
B9: Realized Price — CDN$/lb | C9: =C34 | D9: =D34 -> 88.364046 | E9: 92.15 | F9: =F34 -> 93.555568 | G9: =G34 -> 98.869122 | H9: =H34 -> 104.48014 | I9: =I34 -> 110.40509 | J9: =J34 -> 116.66133 | K9: =K34 -> 123.26719 | L9: =L34 -> 130.24198 | M9: =M34 -> 137.60607 | ... O9: =O34 -> 153.58936
B10: Uranium Revenue — CDN$K | C10: 2677000 | D10: 2874000 | E10: 1370000 | F10: =F8*F9*1000 -> 2806667.1 | G10: =G8*G9*1000 -> 3209950.8 | H10: =H8*H9*1000 -> 3649839.6 | I10: =I8*I9*1000 -> 4129150.4 | J10: =J8*J9*1000 -> 4650898.5 | K10: =K8*K9*1000 -> 5218311 | L10: =L8*L9*1000 -> 5834840.6 | M10: =M8*M9*1000 -> 6504180.5 | ... O10: =O8*O9*1000 -> 8017364.4
B12: REALIZED PRICE DISCOUNT ANALYSIS
C13: 2021A | D13: 2022A | E13: 2023A | F13: 2024A | G13: 2025A | H13: 2026H1 | I13: 2026E
B15: Cameco Realized Price — CDN$/lb | C15: 43.34 | D15: 57.85 | E15: 67.31 | F15: 79.7 | G15: 87 | H15: 92.15 | I15: 92
B16: USD/CAD Exchange Rate (annual avg) | C16: 1.254 | D16: 1.301 | E16: 1.349 | F16: 1.36 | G16: 1.4 | H16: 1.4 | I16: 1.4
B17: Cameco Realized Price — USD$/lb | C17: =C15/C16 -> 34.561404 | D17: =D15/D16 -> 44.465796 | E17: =E15/E16 -> 49.896219 | F17: =F15/F16 -> 58.602941 | G17: =G15/G16 -> 62.142857 | H17: =H15/H16 -> 65.821429 | I17: =I15/I16 -> 65.714286
B18: Uranium Spot Price — USD$/lb (annual avg, UxC) | C18: 33 | D18: 49 | E18: 55 | F18: =C31 -> 73.5 | G18: =D31 -> 81.7 | H18: =E31 -> 86.5 | I18: =F31 -> 86.5
B19: Discount / (Premium) to Spot | C19: =(C17-C18)/C18 -> 0.047315258 | D19: =(D17-D18)/D18 -> -0.092534785 | E19: =(E17-E18)/E18 -> -0.092796011 | F19: =(F17-F18)/F18 -> -0.20268107 | G19: =(G17-G18)/G18 -> -0.23937751 | H19: =(H17-H18)/H18 -> -0.23905863 | I19: =(I17-I18)/I18 -> -0.24029727
B21: Average Discount to Spot (2024-2026) | C21: =AVERAGE(I19,F19:G19) -> -0.22745195
B22: Average Uranium Growth Rate (2021-2026) | C22: 0.05
B23: Targeted Production Volume (M lbs) by 2035 | C23: 261
B24: Cameco Market Share (Base) | C24: 0.13
B25: Cameco Market Share (Upside) | C25: 0.2
B26: Cameco Target Volume 2035 | C26: =CHOOSE(Cover!C17,'Uranium Spot Rate'!C24*'Uranium Spot Rate'!C23,'Uranium Spot Rate'!C25*'Uranium Spot Rate'!C23) -> 52.2
B28: UPSIDE CASE — SPOT PRICE INPUTS & IMPLIED REALIZED PRICE
C29: 2024A | D29: 2025A | E29: H1 2026A | F29: 2026E | G29: 2027E | H29: 2028E | I29: 2029E | J29: 2030E | K29: 2031E | L29: 2032E | M29: 2033E | N29: 2034E | O29: 2035E
B31: Spot Price Assumption — USD$/lb | C31: 73.5 | D31: 81.7 | E31: 86.5 | F31: 86.5 | G31: =F31+(F31*$C$22) -> 90.825 | H31: =G31+(G31*$C$22) -> 95.36625 | I31: =H31+(H31*$C$22) -> 100.13456 | J31: =I31+(I31*$C$22) -> 105.14129 | K31: =J31+(J31*$C$22) -> 110.39836 | L31: =K31+(K31*$C$22) -> 115.91827 | M31: =L31+(L31*$C$22) -> 121.71419 | N31: =M31+(M31*$C$22) -> 127.7999 | O31: =N31+(N31*$C$22) -> 134.18989
B32: Applied Avg Discount to Spot (from historical above) | C32: =$C$21 -> -0.22745195 | D32: =$C$21 -> -0.22745195 | E32: =$C$21 -> -0.22745195 | F32: =$C$21-F27% -> -0.22745195 | G32: =F32+0.5% -> -0.22245195 | H32: =G32+0.5% -> -0.21745195 | I32: =H32+0.5% -> -0.21245195 | J32: =I32+0.5% -> -0.20745195 | K32: =J32+0.5% -> -0.20245195 | L32: =K32+0.5% -> -0.19745195 | M32: =L32+0.5% -> -0.19245195 | N32: =M32+0.5% -> -0.18745195 | O32: =N32+0.5% -> -0.18245195
B33: Implied Realized Price — USD$/lb | C33: =C31*(1+C32) -> 56.782281 | D33: =D31*(1+D32) -> 63.117175 | E33: =E31*(1+E32) -> 66.825406 | F33: =F31*(1+F32) -> 66.825406 | G33: =G31*(1+G32) -> 70.620801 | H33: =H31*(1+H32) -> 74.628673 | I33: =I31*(1+I32) -> 78.860779 | J33: =J31*(1+J32) -> 83.329524 | ... O33: =O31*(1+O32) -> 109.70668
B34: Implied Realized Price — CDN$/lb [÷1.40] | D34: =D33*1.4 -> 88.364046 | E34: =E33*1.4 -> 93.555568 | F34: =F33*1.4 -> 93.555568 | G34: =G33*1.4 -> 98.869122 | H34: =H33*1.4 -> 104.48014 | I34: =I33*1.4 -> 110.40509 | J34: =J33*1.4 -> 116.66133 | K34: =K33*1.4 -> 123.26719 | ... O34: =O33*1.4 -> 153.58936
D41: =

Sheet Westinghouse
B2: WESTINGHOUSE ELECTRIC — EQUITY EARNINGS PROJECTION
B3: Cameco Corporation | 49% equity-accounted investee | $CDN thousands | IFRS equity method
E5: 2025A | F5: 2026E | G5: 2027E | H5: 2028E | I5: 2029E | J5: 2030E | K5: 2031E | L5: 2032E | M5: 2033E | N5: 2034E | O5: 2035E
B7: PROJECTIONS
B8: Equity Earnings → Income Statement row 36 | E8: ='Income Statement'!H36 -> 216386 | F8: ='2026 Interim'!E24*2 -> 148952 | G8: =G10*G9 -> 163847.2 | H8: =H10*H9 -> 180231.92 | I8: =I10*I9 -> 224028.28 | J8: =J10*J9 -> 253151.95 | K8: =K10*K9 -> 286061.71 | L8: =L10*L9 -> 361998.09 | M8: =M10*M9 -> 419917.78 | N8: =N10*N9 -> 487104.63 | O8: =O10*O9 -> 565041.37
B9: Applied Conversion Ratio (EBITDA → Equity Earnings) | E9: =IFERROR(E8/E10,"-") -> 0.27741795 | F9: =CHOOSE(Cover!C17,$B$19,$C$19) -> 0.3 | G9: =CHOOSE(Cover!C17,$B$19,$C$19) -> 0.3 | H9: =CHOOSE(Cover!C17,$B$19,$C$19) -> 0.3 | I9: =CHOOSE(Cover!C17,$B$20,$C$20) -> 0.33 | J9: =CHOOSE(Cover!C17,$B$20,$C$20) -> 0.33 | K9: =CHOOSE(Cover!C17,$B$20,$C$20) -> 0.33 | L9: =CHOOSE(Cover!C17,$B$21,$C$21) -> 0.36 | M9: =CHOOSE(Cover!C17,$B$21,$C$21) -> 0.36 | N9: =CHOOSE(Cover!C17,$B$21,$C$21) -> 0.36 | O9: =CHOOSE(Cover!C17,$B$21,$C$21) -> 0.36
B10: Cameco's 49% Share — Adj. EBITDA | E10: 780000 | F10: =F8/F9 -> 496506.67 | G10: =F10*(1+G11) -> 546157.33 | H10: =G10*(1+H11) -> 600773.07 | I10: =H10*(1+I11) -> 678873.57 | J10: =I10*(1+J11) -> 767127.13 | K10: =J10*(1+K11) -> 866853.66 | L10: =K10*(1+L11) -> 1005550.2 | M10: =L10*(1+M11) -> 1166438.3 | N10: =M10*(1+N11) -> 1353068.4 | O10: =N10*(1+O11) -> 1569559.3
B11: Applied Adj. EBITDA Growth Rate | F11: =CHOOSE(Cover!C17,$B$16,$C$16) -> 0.1 | G11: =CHOOSE(Cover!C17,$B$16,$C$16) -> 0.1 | H11: =CHOOSE(Cover!C17,$B$16,$C$16) -> 0.1 | I11: =CHOOSE(Cover!C17,$B$17,$C$17) -> 0.13 | J11: =CHOOSE(Cover!C17,$B$17,$C$17) -> 0.13 | K11: =CHOOSE(Cover!C17,$B$17,$C$17) -> 0.13 | L11: =CHOOSE(Cover!C17,$B$18,$C$18) -> 0.16 | M11: =CHOOSE(Cover!C17,$B$18,$C$18) -> 0.16 | N11: =CHOOSE(Cover!C17,$B$18,$C$18) -> 0.16 | O11: =CHOOSE(Cover!C17,$B$18,$C$18) -> 0.16
B12: Equity Earnings YoY Growth (check) | F12: =IFERROR(F8/E8-1,"-") -> -0.31163754 | G12: =IFERROR(G8/F8-1,"-") -> 0.1 | H12: =IFERROR(H8/G8-1,"-") -> 0.1 | I12: =IFERROR(I8/H8-1,"-") -> 0.243 | J12: =IFERROR(J8/I8-1,"-") -> 0.13 | K12: =IFERROR(K8/J8-1,"-") -> 0.13 | L12: =IFERROR(L8/K8-1,"-") -> 0.26545455 | M12: =IFERROR(M8/L8-1,"-") -> 0.16 | ... O12: =IFERROR(O8/N8-1,"-") -> 0.16
B14: Base Case | C14: Upside Case | D14: Notes
B15: 0.49 | C15: 0.49 | D15: Joint venture with Brookfield Asset Management (51%)
B16: 0.07 | C16: 0.1 | D16: Base: anchored on nuclear services market ~10-15% growth + Westinghouse pipeline; Upside: accelerated AP1000 / SMR orders
B17: 0.1 | C17: 0.13 | D17: Steady-state growth; new build revenues ramping; maintenance contracts expanding
B18: 0.13 | C18: 0.16 | D18: Mature growth; terminal-period proxy; large new-build cycle largely priced in
B19: 0.28 | C19: 0.3 | D19: 2025A actual = 27.7%; rising as PPA amortization begins to normalize (non-cash D&A from $7.8B acquisition)
B20: 0.3 | C20: 0.33 | D20: Continued PPA amortization wind-down; net income margin improving
B21: 0.32 | C21: 0.36 | D21: Acquisition premium substantially amortized; structurally higher net income conversion
B22: 0.05 | C22: 0.1 | D22: Westinghouse Dividend Growth Rate
B24: 2024A | C24: 2025A
B25: 483000 | C25: 780000
B26: ='Income Statement'!G36 -> -10844 | C26: ='Income Statement'!H36 -> 216386
B27: =IFERROR(B26/B25,"-") -> -0.022451346 | C27: =IFERROR(C26/C25,"-") -> 0.27741795
B29: ASSUMPTIONS
B30: Cameco Ownership in Westinghouse
B31: Adj. EBITDA Growth Rate — Near Term (2026–2028)
B32: Adj. EBITDA Growth Rate — Mid Term (2029–2031)
B33: Adj. EBITDA Growth Rate — Long Term (2032–2035)
B34: EBITDA → Equity Earnings Conversion — Near Term (2026–2028)
B35: EBITDA → Equity Earnings Conversion — Mid Term (2029–2031)
B36: EBITDA → Equity Earnings Conversion — Long Term (2032–2035)
B38: HISTORICAL REFERENCE | D38: Source
B39: Cameco's 49% Share — Adj. EBITDA | D39: Cameco 2025 Annual Report MD&A (Westinghouse segment)
B40: Equity Earnings on Income Statement | D40: Linked from IS; 2024A negative due to acquisition PPA amortization
B41: Actual Conversion Rate | D41: 2024A negative (not meaningful); 2025A = 27.7% baseline for projections
B42: Actual 2026 H1 Revenue
B44: NOTES
B45: Yellow row = equity earnings output — automatically feeds Income Statement row 36 (2026E–2035E) via cross-sheet formula.
B46: Projection logic: Adj. EBITDA grown at selected rate, then multiplied by conversion ratio. Conversion rises as acquisition PPA amortization unwinds over time.
B47: 2024A equity earnings negative due to ~$400-500M/yr non-cash D&A from Cameco/Brookfield $7.8B USD acquisition (Nov 2023). 2025A is first clean run-rate year.
B48: Blue = hardcoded inputs. Green = linked from Income Statement. Toggle Base/Upside via Cover sheet (cell C17).

Sheet Assumptions
B2: CAMECO CORPORATION — INCOME STATEMENT
B3: All figures in $CDN thousands | IFRS | Year ended December 31
C5: 2021A | D5: 2022A | E5: 2023A | F5: 2024A | G5: 2025A | H5: 2026AE | J5: Growth Assumptions | N5: 2026E | O5: 2027E | P5: 2028E | Q5: 2029E | R5: 2030E | S5: 2031E | T5: 2032E | U5: 2033E | V5: 2034E | W5: 2035E
B7: Revenue | J7: Data | K7: Base | L7: Upside
